2024-10-25 13:10:13,733 INFO    StreamThr :54224 [internal.py:wandb_internal():86] W&B internal server running at pid: 54224, started at: 2024-10-25 13:10:13.732479
2024-10-25 13:10:13,736 DEBUG   HandlerThread:54224 [handler.py:handle_request():146] handle_request: status
2024-10-25 13:10:13,762 INFO    WriterThread:54224 [datastore.py:open_for_write():87] open: C:\Users\bais_\source\repos\Progetto\NLP-customer-classification\wandb\run-20241025_131013-3liyyvb3\run-3liyyvb3.wandb
2024-10-25 13:10:13,763 DEBUG   SenderThread:54224 [sender.py:send():378] send: header
2024-10-25 13:10:13,834 DEBUG   SenderThread:54224 [sender.py:send():378] send: run
2024-10-25 13:10:14,790 INFO    SenderThread:54224 [dir_watcher.py:__init__():211] watching files in: C:\Users\bais_\source\repos\Progetto\NLP-customer-classification\wandb\run-20241025_131013-3liyyvb3\files
2024-10-25 13:10:14,790 INFO    SenderThread:54224 [sender.py:_start_run_threads():1099] run started: 3liyyvb3 with start time 1729854613.732478
2024-10-25 13:10:14,826 DEBUG   HandlerThread:54224 [handler.py:handle_request():146] handle_request: check_version
2024-10-25 13:10:14,826 DEBUG   SenderThread:54224 [sender.py:send_request():405] send_request: check_version
2024-10-25 13:10:15,686 DEBUG   HandlerThread:54224 [handler.py:handle_request():146] handle_request: run_start
2024-10-25 13:10:16,259 DEBUG   HandlerThread:54224 [system_info.py:__init__():26] System info init
2024-10-25 13:10:16,259 DEBUG   HandlerThread:54224 [system_info.py:__init__():41] System info init done
2024-10-25 13:10:16,259 INFO    HandlerThread:54224 [system_monitor.py:start():194] Starting system monitor
2024-10-25 13:10:16,260 INFO    SystemMonitor:54224 [system_monitor.py:_start():158] Starting system asset monitoring threads
2024-10-25 13:10:16,260 INFO    HandlerThread:54224 [system_monitor.py:probe():214] Collecting system info
2024-10-25 13:10:16,291 INFO    SystemMonitor:54224 [interfaces.py:start():190] Started cpu monitoring
2024-10-25 13:10:16,292 INFO    SystemMonitor:54224 [interfaces.py:start():190] Started disk monitoring
2024-10-25 13:10:16,294 INFO    SystemMonitor:54224 [interfaces.py:start():190] Started gpu monitoring
2024-10-25 13:10:16,295 INFO    SystemMonitor:54224 [interfaces.py:start():190] Started memory monitoring
2024-10-25 13:10:16,311 INFO    SystemMonitor:54224 [interfaces.py:start():190] Started network monitoring
2024-10-25 13:10:16,311 DEBUG   HandlerThread:54224 [system_info.py:probe():150] Probing system
2024-10-25 13:10:16,330 ERROR   gpu       :54224 [interfaces.py:monitor():144] Failed to sample metric: Not Supported
2024-10-25 13:10:16,331 ERROR   gpu       :54224 [interfaces.py:monitor():144] Failed to sample metric: Not Supported
2024-10-25 13:10:16,334 DEBUG   HandlerThread:54224 [system_info.py:_probe_git():135] Probing git
2024-10-25 13:10:16,473 DEBUG   HandlerThread:54224 [system_info.py:_probe_git():143] Probing git done
2024-10-25 13:10:16,473 DEBUG   HandlerThread:54224 [system_info.py:probe():198] Probing system done
2024-10-25 13:10:16,474 DEBUG   HandlerThread:54224 [system_monitor.py:probe():223] {'os': 'Windows-10-10.0.19045-SP0', 'python': '3.11.5', 'heartbeatAt': '2024-10-25T11:10:16.328852', 'startedAt': '2024-10-25T11:10:13.694676', 'docker': None, 'cuda': None, 'args': ('True',), 'state': 'running', 'program': 'C:\\Users\\bais_\\source\\repos\\Progetto\\NLP-customer-classification\\src\\scripts\\train.py', 'codePathLocal': 'src\\scripts\\train.py', 'codePath': 'src\\scripts\\train.py', 'git': {'remote': 'https://github.com/giacomobais/NLP-customer-classification.git', 'commit': '92186a1c3fbd5d4e97b4899777b15350347073c8'}, 'email': '57444236+giacomobais@users.noreply.github.com', 'root': 'C:/Users/bais_/source/repos/Progetto/NLP-customer-classification', 'host': 'DESKTOP-3I1KQF4', 'username': 'bais_', 'executable': 'C:\\Users\\bais_\\anaconda3\\python.exe', 'cpu_count': 4, 'cpu_count_logical': 8, 'cpu_freq': {'current': 2592.0, 'min': 0.0, 'max': 2592.0}, 'cpu_freq_per_core': [{'current': 2592.0, 'min': 0.0, 'max': 2592.0}], 'disk': {'/': {'total': 464.33886337280273, 'used': 430.66711044311523}}, 'gpu': 'NVIDIA GeForce GTX 950M', 'gpu_count': 1, 'gpu_devices': [{'name': 'NVIDIA GeForce GTX 950M', 'memory_total': 4294967296}], 'memory': {'total': 7.901309967041016}}
2024-10-25 13:10:16,474 INFO    HandlerThread:54224 [system_monitor.py:probe():224] Finished collecting system info
2024-10-25 13:10:16,474 INFO    HandlerThread:54224 [system_monitor.py:probe():227] Publishing system info
2024-10-25 13:10:16,474 DEBUG   HandlerThread:54224 [system_info.py:_save_conda():207] Saving list of conda packages installed into the current environment
2024-10-25 13:10:16,810 INFO    Thread-16 :54224 [dir_watcher.py:_on_file_created():271] file/dir created: C:\Users\bais_\source\repos\Progetto\NLP-customer-classification\wandb\run-20241025_131013-3liyyvb3\files\conda-environment.yaml
2024-10-25 13:10:18,380 ERROR   gpu       :54224 [interfaces.py:monitor():144] Failed to sample metric: Unknown Error
2024-10-25 13:10:18,380 ERROR   gpu       :54224 [interfaces.py:monitor():144] Failed to sample metric: Unknown Error
2024-10-25 13:10:18,381 ERROR   gpu       :54224 [interfaces.py:monitor():144] Failed to sample metric: Not Supported
2024-10-25 13:10:18,381 ERROR   gpu       :54224 [interfaces.py:monitor():144] Failed to sample metric: Not Supported
2024-10-25 13:10:20,425 ERROR   gpu       :54224 [interfaces.py:monitor():144] Failed to sample metric: Unknown Error
2024-10-25 13:10:20,425 ERROR   gpu       :54224 [interfaces.py:monitor():144] Failed to sample metric: Unknown Error
2024-10-25 13:10:20,425 ERROR   gpu       :54224 [interfaces.py:monitor():144] Failed to sample metric: Not Supported
2024-10-25 13:10:20,425 ERROR   gpu       :54224 [interfaces.py:monitor():144] Failed to sample metric: Not Supported
2024-10-25 13:10:22,471 ERROR   gpu       :54224 [interfaces.py:monitor():144] Failed to sample metric: Unknown Error
2024-10-25 13:10:22,472 ERROR   gpu       :54224 [interfaces.py:monitor():144] Failed to sample metric: Unknown Error
2024-10-25 13:10:22,472 ERROR   gpu       :54224 [interfaces.py:monitor():144] Failed to sample metric: Not Supported
2024-10-25 13:10:22,472 ERROR   gpu       :54224 [interfaces.py:monitor():144] Failed to sample metric: Not Supported
2024-10-25 13:10:24,516 ERROR   gpu       :54224 [interfaces.py:monitor():144] Failed to sample metric: Unknown Error
2024-10-25 13:10:24,517 ERROR   gpu       :54224 [interfaces.py:monitor():144] Failed to sample metric: Unknown Error
2024-10-25 13:10:24,517 ERROR   gpu       :54224 [interfaces.py:monitor():144] Failed to sample metric: Not Supported
2024-10-25 13:10:24,517 ERROR   gpu       :54224 [interfaces.py:monitor():144] Failed to sample metric: Not Supported
2024-10-25 13:10:26,555 ERROR   gpu       :54224 [interfaces.py:monitor():144] Failed to sample metric: Unknown Error
2024-10-25 13:10:26,555 ERROR   gpu       :54224 [interfaces.py:monitor():144] Failed to sample metric: Unknown Error
2024-10-25 13:10:26,555 ERROR   gpu       :54224 [interfaces.py:monitor():144] Failed to sample metric: Not Supported
2024-10-25 13:10:26,555 ERROR   gpu       :54224 [interfaces.py:monitor():144] Failed to sample metric: Not Supported
2024-10-25 13:10:28,570 ERROR   gpu       :54224 [interfaces.py:monitor():144] Failed to sample metric: Unknown Error
2024-10-25 13:10:28,612 ERROR   gpu       :54224 [interfaces.py:monitor():144] Failed to sample metric: Unknown Error
2024-10-25 13:10:28,612 ERROR   gpu       :54224 [interfaces.py:monitor():144] Failed to sample metric: Not Supported
2024-10-25 13:10:28,612 ERROR   gpu       :54224 [interfaces.py:monitor():144] Failed to sample metric: Not Supported
2024-10-25 13:10:30,662 ERROR   gpu       :54224 [interfaces.py:monitor():144] Failed to sample metric: Unknown Error
2024-10-25 13:10:30,662 ERROR   gpu       :54224 [interfaces.py:monitor():144] Failed to sample metric: Unknown Error
2024-10-25 13:10:30,663 ERROR   gpu       :54224 [interfaces.py:monitor():144] Failed to sample metric: Not Supported
2024-10-25 13:10:30,663 ERROR   gpu       :54224 [interfaces.py:monitor():144] Failed to sample metric: Not Supported
2024-10-25 13:10:32,699 ERROR   gpu       :54224 [interfaces.py:monitor():144] Failed to sample metric: Unknown Error
2024-10-25 13:10:32,699 ERROR   gpu       :54224 [interfaces.py:monitor():144] Failed to sample metric: Unknown Error
2024-10-25 13:10:32,699 ERROR   gpu       :54224 [interfaces.py:monitor():144] Failed to sample metric: Not Supported
2024-10-25 13:10:32,699 ERROR   gpu       :54224 [interfaces.py:monitor():144] Failed to sample metric: Not Supported
2024-10-25 13:10:34,731 ERROR   gpu       :54224 [interfaces.py:monitor():144] Failed to sample metric: Unknown Error
2024-10-25 13:10:34,731 ERROR   gpu       :54224 [interfaces.py:monitor():144] Failed to sample metric: Unknown Error
2024-10-25 13:10:34,731 ERROR   gpu       :54224 [interfaces.py:monitor():144] Failed to sample metric: Not Supported
2024-10-25 13:10:34,732 ERROR   gpu       :54224 [interfaces.py:monitor():144] Failed to sample metric: Not Supported
2024-10-25 13:10:36,777 ERROR   gpu       :54224 [interfaces.py:monitor():144] Failed to sample metric: Unknown Error
2024-10-25 13:10:36,777 ERROR   gpu       :54224 [interfaces.py:monitor():144] Failed to sample metric: Unknown Error
2024-10-25 13:10:36,777 ERROR   gpu       :54224 [interfaces.py:monitor():144] Failed to sample metric: Not Supported
2024-10-25 13:10:36,777 ERROR   gpu       :54224 [interfaces.py:monitor():144] Failed to sample metric: Not Supported
2024-10-25 13:10:38,817 ERROR   gpu       :54224 [interfaces.py:monitor():144] Failed to sample metric: Unknown Error
2024-10-25 13:10:38,817 ERROR   gpu       :54224 [interfaces.py:monitor():144] Failed to sample metric: Unknown Error
2024-10-25 13:10:38,817 ERROR   gpu       :54224 [interfaces.py:monitor():144] Failed to sample metric: Not Supported
2024-10-25 13:10:38,817 ERROR   gpu       :54224 [interfaces.py:monitor():144] Failed to sample metric: Not Supported
2024-10-25 13:10:40,863 ERROR   gpu       :54224 [interfaces.py:monitor():144] Failed to sample metric: Unknown Error
2024-10-25 13:10:40,863 ERROR   gpu       :54224 [interfaces.py:monitor():144] Failed to sample metric: Unknown Error
2024-10-25 13:10:40,864 ERROR   gpu       :54224 [interfaces.py:monitor():144] Failed to sample metric: Not Supported
2024-10-25 13:10:40,864 ERROR   gpu       :54224 [interfaces.py:monitor():144] Failed to sample metric: Not Supported
2024-10-25 13:10:41,918 DEBUG   HandlerThread:54224 [system_info.py:_save_conda():219] Saving conda packages done
2024-10-25 13:10:41,920 INFO    HandlerThread:54224 [system_monitor.py:probe():229] Finished publishing system info
2024-10-25 13:10:41,928 DEBUG   HandlerThread:54224 [handler.py:handle_request():146] handle_request: status_report
2024-10-25 13:10:41,929 DEBUG   HandlerThread:54224 [handler.py:handle_request():146] handle_request: keepalive
2024-10-25 13:10:41,929 DEBUG   HandlerThread:54224 [handler.py:handle_request():146] handle_request: status_report
2024-10-25 13:10:41,929 DEBUG   HandlerThread:54224 [handler.py:handle_request():146] handle_request: keepalive
2024-10-25 13:10:41,930 DEBUG   HandlerThread:54224 [handler.py:handle_request():146] handle_request: status_report
2024-10-25 13:10:41,930 DEBUG   HandlerThread:54224 [handler.py:handle_request():146] handle_request: keepalive
2024-10-25 13:10:41,930 DEBUG   HandlerThread:54224 [handler.py:handle_request():146] handle_request: status_report
2024-10-25 13:10:41,930 DEBUG   HandlerThread:54224 [handler.py:handle_request():146] handle_request: keepalive
2024-10-25 13:10:41,930 DEBUG   HandlerThread:54224 [handler.py:handle_request():146] handle_request: status_report
2024-10-25 13:10:41,930 DEBUG   HandlerThread:54224 [handler.py:handle_request():146] handle_request: keepalive
2024-10-25 13:10:41,931 DEBUG   SenderThread:54224 [sender.py:send():378] send: files
2024-10-25 13:10:41,932 INFO    SenderThread:54224 [sender.py:_save_file():1365] saving file wandb-metadata.json with policy now
2024-10-25 13:10:42,056 INFO    Thread-16 :54224 [dir_watcher.py:_on_file_modified():288] file/dir modified: C:\Users\bais_\source\repos\Progetto\NLP-customer-classification\wandb\run-20241025_131013-3liyyvb3\files\conda-environment.yaml
2024-10-25 13:10:42,057 INFO    Thread-16 :54224 [dir_watcher.py:_on_file_created():271] file/dir created: C:\Users\bais_\source\repos\Progetto\NLP-customer-classification\wandb\run-20241025_131013-3liyyvb3\files\wandb-metadata.json
2024-10-25 13:10:42,194 ERROR   wandb-upload_0:54224 [internal_api.py:execute():373] 404 response executing GraphQL.
2024-10-25 13:10:42,194 ERROR   wandb-upload_0:54224 [internal_api.py:execute():374] {"errors":[{"message":"run bert-ticket-classifier/3liyyvb3 not found during createRunFiles","path":["createRunFiles"]}],"data":{"createRunFiles":null}}
2024-10-25 13:10:42,205 ERROR   Thread-15 (_thread_body):54224 [step_upload.py:_handle_event():200] Failed to upload file: C:\Users\bais_\AppData\Local\Temp\tmpzvo_i_15wandb\qqy5c4a6-wandb-metadata.json
Traceback (most recent call last):
  File "C:\Users\bais_\anaconda3\Lib\site-packages\wandb\sdk\lib\retry.py", line 131, in __call__
    result = self._call_fn(*args, **kwargs)
             ^^^^^^^^^^^^^^^^^^^^^^^^^^^^^^
  File "C:\Users\bais_\anaconda3\Lib\site-packages\wandb\sdk\internal\internal_api.py", line 369, in execute
    return self.client.execute(*args, **kwargs)  # type: ignore
           ^^^^^^^^^^^^^^^^^^^^^^^^^^^^^^^^^^^^
  File "C:\Users\bais_\anaconda3\Lib\site-packages\wandb\vendor\gql-0.2.0\wandb_gql\client.py", line 52, in execute
    result = self._get_result(document, *args, **kwargs)
             ^^^^^^^^^^^^^^^^^^^^^^^^^^^^^^^^^^^^^^^^^^^
  File "C:\Users\bais_\anaconda3\Lib\site-packages\wandb\vendor\gql-0.2.0\wandb_gql\client.py", line 60, in _get_result
    return self.transport.execute(document, *args, **kwargs)
           ^^^^^^^^^^^^^^^^^^^^^^^^^^^^^^^^^^^^^^^^^^^^^^^^^
  File "C:\Users\bais_\anaconda3\Lib\site-packages\wandb\sdk\lib\gql_request.py", line 59, in execute
    request.raise_for_status()
  File "C:\Users\bais_\anaconda3\Lib\site-packages\requests\models.py", line 1021, in raise_for_status
    raise HTTPError(http_error_msg, response=self)
requests.exceptions.HTTPError: 404 Client Error: Not Found for url: https://api.wandb.ai/graphql

During handling of the above exception, another exception occurred:

Traceback (most recent call last):
  File "C:\Users\bais_\anaconda3\Lib\concurrent\futures\thread.py", line 58, in run
    result = self.fn(*self.args, **self.kwargs)
             ^^^^^^^^^^^^^^^^^^^^^^^^^^^^^^^^^^
  File "C:\Users\bais_\anaconda3\Lib\site-packages\wandb\filesync\step_upload.py", line 288, in run_and_notify
    self._do_upload_sync(event)
  File "C:\Users\bais_\anaconda3\Lib\site-packages\wandb\filesync\step_upload.py", line 330, in _do_upload_sync
    job.run()
  File "C:\Users\bais_\anaconda3\Lib\site-packages\wandb\filesync\upload_job.py", line 57, in run
    self.push()
  File "C:\Users\bais_\anaconda3\Lib\site-packages\wandb\filesync\upload_job.py", line 106, in push
    _, upload_headers, result = self._api.upload_urls(project, [self.save_name])
                                ^^^^^^^^^^^^^^^^^^^^^^^^^^^^^^^^^^^^^^^^^^^^^^^^
  File "C:\Users\bais_\anaconda3\Lib\site-packages\wandb\apis\normalize.py", line 73, in wrapper
    raise err
  File "C:\Users\bais_\anaconda3\Lib\site-packages\wandb\apis\normalize.py", line 41, in wrapper
    return func(*args, **kwargs)
           ^^^^^^^^^^^^^^^^^^^^^
  File "C:\Users\bais_\anaconda3\Lib\site-packages\wandb\sdk\internal\internal_api.py", line 2384, in upload_urls
    query_result = self.gql(
                   ^^^^^^^^^
  File "C:\Users\bais_\anaconda3\Lib\site-packages\wandb\sdk\internal\internal_api.py", line 341, in gql
    ret = self._retry_gql(
          ^^^^^^^^^^^^^^^^
  File "C:\Users\bais_\anaconda3\Lib\site-packages\wandb\sdk\lib\retry.py", line 147, in __call__
    retry_timedelta_triggered = check_retry_fn(e)
                                ^^^^^^^^^^^^^^^^^
  File "C:\Users\bais_\anaconda3\Lib\site-packages\wandb\util.py", line 910, in no_retry_auth
    raise CommError(
wandb.errors.CommError: It appears that you do not have permission to access the requested resource. Please reach out to the project owner to grant you access. If you have the correct permissions, verify that there are no issues with your networking setup.(Error 404: Not Found)
2024-10-25 13:10:42,492 DEBUG   HandlerThread:54224 [handler.py:handle_request():146] handle_request: python_packages
2024-10-25 13:10:42,492 DEBUG   SenderThread:54224 [sender.py:send_request():405] send_request: python_packages
2024-10-25 13:10:42,493 DEBUG   HandlerThread:54224 [handler.py:handle_request():146] handle_request: stop_status
2024-10-25 13:10:42,494 DEBUG   HandlerThread:54224 [handler.py:handle_request():146] handle_request: internal_messages
2024-10-25 13:10:42,495 DEBUG   SenderThread:54224 [sender.py:send_request():405] send_request: stop_status
2024-10-25 13:10:42,902 ERROR   gpu       :54224 [interfaces.py:monitor():144] Failed to sample metric: Unknown Error
2024-10-25 13:10:42,902 ERROR   gpu       :54224 [interfaces.py:monitor():144] Failed to sample metric: Unknown Error
2024-10-25 13:10:42,902 ERROR   gpu       :54224 [interfaces.py:monitor():144] Failed to sample metric: Not Supported
2024-10-25 13:10:42,902 ERROR   gpu       :54224 [interfaces.py:monitor():144] Failed to sample metric: Not Supported
2024-10-25 13:10:43,060 INFO    Thread-16 :54224 [dir_watcher.py:_on_file_created():271] file/dir created: C:\Users\bais_\source\repos\Progetto\NLP-customer-classification\wandb\run-20241025_131013-3liyyvb3\files\requirements.txt
2024-10-25 13:10:43,512 DEBUG   HandlerThread:54224 [handler.py:handle_request():146] handle_request: poll_exit
2024-10-25 13:10:43,670 DEBUG   SenderThread:54224 [sender.py:send():378] send: telemetry
2024-10-25 13:10:43,672 DEBUG   SenderThread:54224 [sender.py:send():378] send: telemetry
2024-10-25 13:10:43,673 DEBUG   SenderThread:54224 [sender.py:send():378] send: exit
2024-10-25 13:10:43,673 INFO    SenderThread:54224 [sender.py:send_exit():585] handling exit code: 1
2024-10-25 13:10:43,673 INFO    SenderThread:54224 [sender.py:send_exit():587] handling runtime: 26
2024-10-25 13:10:43,675 INFO    SenderThread:54224 [sender.py:_save_file():1365] saving file wandb-summary.json with policy end
2024-10-25 13:10:43,676 INFO    SenderThread:54224 [sender.py:send_exit():593] send defer
2024-10-25 13:10:43,676 DEBUG   SenderThread:54224 [sender.py:send_request():405] send_request: poll_exit
2024-10-25 13:10:43,677 DEBUG   HandlerThread:54224 [handler.py:handle_request():146] handle_request: defer
2024-10-25 13:10:43,677 INFO    HandlerThread:54224 [handler.py:handle_request_defer():172] handle defer: 0
2024-10-25 13:10:43,678 DEBUG   SenderThread:54224 [sender.py:send_request():405] send_request: defer
2024-10-25 13:10:43,678 INFO    SenderThread:54224 [sender.py:send_request_defer():609] handle sender defer: 0
2024-10-25 13:10:43,678 INFO    SenderThread:54224 [sender.py:transition_state():613] send defer: 1
2024-10-25 13:10:43,678 DEBUG   HandlerThread:54224 [handler.py:handle_request():146] handle_request: defer
2024-10-25 13:10:43,679 INFO    HandlerThread:54224 [handler.py:handle_request_defer():172] handle defer: 1
2024-10-25 13:10:43,679 DEBUG   SenderThread:54224 [sender.py:send_request():405] send_request: defer
2024-10-25 13:10:43,679 INFO    SenderThread:54224 [sender.py:send_request_defer():609] handle sender defer: 1
2024-10-25 13:10:43,680 INFO    SenderThread:54224 [sender.py:transition_state():613] send defer: 2
2024-10-25 13:10:43,680 DEBUG   HandlerThread:54224 [handler.py:handle_request():146] handle_request: defer
2024-10-25 13:10:43,680 INFO    HandlerThread:54224 [handler.py:handle_request_defer():172] handle defer: 2
2024-10-25 13:10:43,680 INFO    HandlerThread:54224 [system_monitor.py:finish():203] Stopping system monitor
2024-10-25 13:10:43,680 DEBUG   SystemMonitor:54224 [system_monitor.py:_start():172] Starting system metrics aggregation loop
2024-10-25 13:10:43,703 INFO    HandlerThread:54224 [interfaces.py:finish():202] Joined cpu monitor
2024-10-25 13:10:43,704 DEBUG   SystemMonitor:54224 [system_monitor.py:_start():179] Finished system metrics aggregation loop
2024-10-25 13:10:43,704 INFO    HandlerThread:54224 [interfaces.py:finish():202] Joined disk monitor
2024-10-25 13:10:43,705 DEBUG   SystemMonitor:54224 [system_monitor.py:_start():183] Publishing last batch of metrics
2024-10-25 13:10:44,077 INFO    Thread-16 :54224 [dir_watcher.py:_on_file_created():271] file/dir created: C:\Users\bais_\source\repos\Progetto\NLP-customer-classification\wandb\run-20241025_131013-3liyyvb3\files\output.log
2024-10-25 13:10:44,078 INFO    Thread-16 :54224 [dir_watcher.py:_on_file_created():271] file/dir created: C:\Users\bais_\source\repos\Progetto\NLP-customer-classification\wandb\run-20241025_131013-3liyyvb3\files\wandb-summary.json
2024-10-25 13:10:44,323 ERROR   gpu       :54224 [interfaces.py:aggregate():161] Failed to serialize metric: division by zero
2024-10-25 13:10:44,323 INFO    HandlerThread:54224 [interfaces.py:finish():202] Joined gpu monitor
2024-10-25 13:10:44,324 INFO    HandlerThread:54224 [interfaces.py:finish():202] Joined memory monitor
2024-10-25 13:10:44,324 INFO    HandlerThread:54224 [interfaces.py:finish():202] Joined network monitor
2024-10-25 13:10:44,325 DEBUG   SenderThread:54224 [sender.py:send_request():405] send_request: defer
2024-10-25 13:10:44,325 INFO    SenderThread:54224 [sender.py:send_request_defer():609] handle sender defer: 2
2024-10-25 13:10:44,325 INFO    SenderThread:54224 [sender.py:transition_state():613] send defer: 3
2024-10-25 13:10:44,325 DEBUG   SenderThread:54224 [sender.py:send():378] send: stats
2024-10-25 13:10:44,325 DEBUG   HandlerThread:54224 [handler.py:handle_request():146] handle_request: defer
2024-10-25 13:10:44,326 INFO    HandlerThread:54224 [handler.py:handle_request_defer():172] handle defer: 3
2024-10-25 13:10:44,326 DEBUG   SenderThread:54224 [sender.py:send_request():405] send_request: defer
2024-10-25 13:10:44,326 INFO    SenderThread:54224 [sender.py:send_request_defer():609] handle sender defer: 3
2024-10-25 13:10:44,326 INFO    SenderThread:54224 [sender.py:transition_state():613] send defer: 4
2024-10-25 13:10:44,326 DEBUG   HandlerThread:54224 [handler.py:handle_request():146] handle_request: defer
2024-10-25 13:10:44,326 INFO    HandlerThread:54224 [handler.py:handle_request_defer():172] handle defer: 4
2024-10-25 13:10:44,327 DEBUG   SenderThread:54224 [sender.py:send_request():405] send_request: defer
2024-10-25 13:10:44,327 INFO    SenderThread:54224 [sender.py:send_request_defer():609] handle sender defer: 4
2024-10-25 13:10:44,327 INFO    SenderThread:54224 [sender.py:transition_state():613] send defer: 5
2024-10-25 13:10:44,327 DEBUG   HandlerThread:54224 [handler.py:handle_request():146] handle_request: defer
2024-10-25 13:10:44,327 INFO    HandlerThread:54224 [handler.py:handle_request_defer():172] handle defer: 5
2024-10-25 13:10:44,328 DEBUG   SenderThread:54224 [sender.py:send():378] send: summary
2024-10-25 13:10:44,328 INFO    SenderThread:54224 [sender.py:_save_file():1365] saving file wandb-summary.json with policy end
2024-10-25 13:10:44,329 DEBUG   SenderThread:54224 [sender.py:send_request():405] send_request: defer
2024-10-25 13:10:44,329 INFO    SenderThread:54224 [sender.py:send_request_defer():609] handle sender defer: 5
2024-10-25 13:10:44,329 INFO    SenderThread:54224 [sender.py:transition_state():613] send defer: 6
2024-10-25 13:10:44,329 DEBUG   HandlerThread:54224 [handler.py:handle_request():146] handle_request: defer
2024-10-25 13:10:44,329 INFO    HandlerThread:54224 [handler.py:handle_request_defer():172] handle defer: 6
2024-10-25 13:10:44,330 DEBUG   SenderThread:54224 [sender.py:send_request():405] send_request: defer
2024-10-25 13:10:44,330 INFO    SenderThread:54224 [sender.py:send_request_defer():609] handle sender defer: 6
2024-10-25 13:10:44,334 DEBUG   HandlerThread:54224 [handler.py:handle_request():146] handle_request: status_report
2024-10-25 13:10:44,468 ERROR   SenderThread:54224 [internal_api.py:execute():373] 409 response executing GraphQL.
2024-10-25 13:10:44,468 ERROR   SenderThread:54224 [internal_api.py:execute():374] {"errors":[{"message":"run 3liyyvb3 was previously created and deleted; try a new run name","path":["upsertBucket"]}],"data":{"upsertBucket":null}}
2024-10-25 13:10:44,481 ERROR   FileStreamThread:54224 [file_stream.py:_handle_response():504] dropped chunk 404 Client Error: Not Found for url: https://api.wandb.ai/files/gbais/bert-ticket-classifier/3liyyvb3/file_stream
NoneType: None
2024-10-25 13:10:44,516 DEBUG   HandlerThread:54224 [handler.py:handle_request():146] handle_request: poll_exit
2024-10-25 13:10:45,098 INFO    Thread-16 :54224 [dir_watcher.py:_on_file_modified():288] file/dir modified: C:\Users\bais_\source\repos\Progetto\NLP-customer-classification\wandb\run-20241025_131013-3liyyvb3\files\wandb-summary.json
2024-10-25 13:10:45,681 ERROR   SenderThread:54224 [internal_api.py:execute():373] 409 response executing GraphQL.
2024-10-25 13:10:45,682 ERROR   SenderThread:54224 [internal_api.py:execute():374] {"errors":[{"message":"run 3liyyvb3 was previously created and deleted; try a new run name","path":["upsertBucket"]}],"data":{"upsertBucket":null}}
2024-10-25 13:10:45,814 ERROR   FileStreamThread:54224 [file_stream.py:_handle_response():504] dropped chunk 404 Client Error: Not Found for url: https://api.wandb.ai/files/gbais/bert-ticket-classifier/3liyyvb3/file_stream
NoneType: None
2024-10-25 13:10:46,111 INFO    Thread-16 :54224 [dir_watcher.py:_on_file_modified():288] file/dir modified: C:\Users\bais_\source\repos\Progetto\NLP-customer-classification\wandb\run-20241025_131013-3liyyvb3\files\output.log
2024-10-25 13:10:48,139 ERROR   SenderThread:54224 [internal_api.py:execute():373] 409 response executing GraphQL.
2024-10-25 13:10:48,139 ERROR   SenderThread:54224 [internal_api.py:execute():374] {"errors":[{"message":"run 3liyyvb3 was previously created and deleted; try a new run name","path":["upsertBucket"]}],"data":{"upsertBucket":null}}
2024-10-25 13:10:48,139 INFO    SenderThread:54224 [retry.py:__call__():172] Retry attempt failed:
Traceback (most recent call last):
  File "C:\Users\bais_\anaconda3\Lib\site-packages\wandb\sdk\lib\retry.py", line 131, in __call__
    result = self._call_fn(*args, **kwargs)
             ^^^^^^^^^^^^^^^^^^^^^^^^^^^^^^
  File "C:\Users\bais_\anaconda3\Lib\site-packages\wandb\sdk\internal\internal_api.py", line 369, in execute
    return self.client.execute(*args, **kwargs)  # type: ignore
           ^^^^^^^^^^^^^^^^^^^^^^^^^^^^^^^^^^^^
  File "C:\Users\bais_\anaconda3\Lib\site-packages\wandb\vendor\gql-0.2.0\wandb_gql\client.py", line 52, in execute
    result = self._get_result(document, *args, **kwargs)
             ^^^^^^^^^^^^^^^^^^^^^^^^^^^^^^^^^^^^^^^^^^^
  File "C:\Users\bais_\anaconda3\Lib\site-packages\wandb\vendor\gql-0.2.0\wandb_gql\client.py", line 60, in _get_result
    return self.transport.execute(document, *args, **kwargs)
           ^^^^^^^^^^^^^^^^^^^^^^^^^^^^^^^^^^^^^^^^^^^^^^^^^
  File "C:\Users\bais_\anaconda3\Lib\site-packages\wandb\sdk\lib\gql_request.py", line 59, in execute
    request.raise_for_status()
  File "C:\Users\bais_\anaconda3\Lib\site-packages\requests\models.py", line 1021, in raise_for_status
    raise HTTPError(http_error_msg, response=self)
requests.exceptions.HTTPError: 409 Client Error: Conflict for url: https://api.wandb.ai/graphql
2024-10-25 13:10:49,559 DEBUG   HandlerThread:54224 [handler.py:handle_request():146] handle_request: keepalive
2024-10-25 13:10:52,480 ERROR   SenderThread:54224 [internal_api.py:execute():373] 409 response executing GraphQL.
2024-10-25 13:10:52,480 ERROR   SenderThread:54224 [internal_api.py:execute():374] {"errors":[{"message":"run 3liyyvb3 was previously created and deleted; try a new run name","path":["upsertBucket"]}],"data":{"upsertBucket":null}}
2024-10-25 13:10:54,582 DEBUG   HandlerThread:54224 [handler.py:handle_request():146] handle_request: keepalive
2024-10-25 13:10:59,617 DEBUG   HandlerThread:54224 [handler.py:handle_request():146] handle_request: keepalive
2024-10-25 13:11:01,687 ERROR   SenderThread:54224 [internal_api.py:execute():373] 409 response executing GraphQL.
2024-10-25 13:11:01,687 ERROR   SenderThread:54224 [internal_api.py:execute():374] {"errors":[{"message":"run 3liyyvb3 was previously created and deleted; try a new run name","path":["upsertBucket"]}],"data":{"upsertBucket":null}}
2024-10-25 13:11:04,664 DEBUG   HandlerThread:54224 [handler.py:handle_request():146] handle_request: keepalive
2024-10-25 13:11:09,708 DEBUG   HandlerThread:54224 [handler.py:handle_request():146] handle_request: keepalive
2024-10-25 13:11:14,761 DEBUG   HandlerThread:54224 [handler.py:handle_request():146] handle_request: keepalive
2024-10-25 13:11:18,247 ERROR   SenderThread:54224 [internal_api.py:execute():373] 409 response executing GraphQL.
2024-10-25 13:11:18,248 ERROR   SenderThread:54224 [internal_api.py:execute():374] {"errors":[{"message":"run 3liyyvb3 was previously created and deleted; try a new run name","path":["upsertBucket"]}],"data":{"upsertBucket":null}}
2024-10-25 13:11:19,812 DEBUG   HandlerThread:54224 [handler.py:handle_request():146] handle_request: keepalive
2024-10-25 13:11:24,876 DEBUG   HandlerThread:54224 [handler.py:handle_request():146] handle_request: keepalive
2024-10-25 13:11:29,940 DEBUG   HandlerThread:54224 [handler.py:handle_request():146] handle_request: keepalive
2024-10-25 13:11:34,970 DEBUG   HandlerThread:54224 [handler.py:handle_request():146] handle_request: keepalive
2024-10-25 13:11:40,031 DEBUG   HandlerThread:54224 [handler.py:handle_request():146] handle_request: keepalive
2024-10-25 13:11:45,087 DEBUG   HandlerThread:54224 [handler.py:handle_request():146] handle_request: keepalive
2024-10-25 13:11:50,141 DEBUG   HandlerThread:54224 [handler.py:handle_request():146] handle_request: keepalive
2024-10-25 13:11:53,770 ERROR   SenderThread:54224 [internal_api.py:execute():373] 409 response executing GraphQL.
2024-10-25 13:11:53,770 ERROR   SenderThread:54224 [internal_api.py:execute():374] {"errors":[{"message":"run 3liyyvb3 was previously created and deleted; try a new run name","path":["upsertBucket"]}],"data":{"upsertBucket":null}}
2024-10-25 13:11:55,190 DEBUG   HandlerThread:54224 [handler.py:handle_request():146] handle_request: keepalive
2024-10-25 13:12:00,233 DEBUG   HandlerThread:54224 [handler.py:handle_request():146] handle_request: keepalive
2024-10-25 13:12:05,286 DEBUG   HandlerThread:54224 [handler.py:handle_request():146] handle_request: keepalive
2024-10-25 13:12:10,327 DEBUG   HandlerThread:54224 [handler.py:handle_request():146] handle_request: keepalive
2024-10-25 13:12:15,360 DEBUG   HandlerThread:54224 [handler.py:handle_request():146] handle_request: keepalive
2024-10-25 13:12:20,401 DEBUG   HandlerThread:54224 [handler.py:handle_request():146] handle_request: keepalive
2024-10-25 13:12:25,436 DEBUG   HandlerThread:54224 [handler.py:handle_request():146] handle_request: keepalive
2024-10-25 13:12:30,500 DEBUG   HandlerThread:54224 [handler.py:handle_request():146] handle_request: keepalive
2024-10-25 13:12:35,542 DEBUG   HandlerThread:54224 [handler.py:handle_request():146] handle_request: keepalive
2024-10-25 13:12:40,590 DEBUG   HandlerThread:54224 [handler.py:handle_request():146] handle_request: keepalive
2024-10-25 13:12:45,638 DEBUG   HandlerThread:54224 [handler.py:handle_request():146] handle_request: keepalive
2024-10-25 13:12:50,655 DEBUG   HandlerThread:54224 [handler.py:handle_request():146] handle_request: keepalive
2024-10-25 13:12:55,704 DEBUG   HandlerThread:54224 [handler.py:handle_request():146] handle_request: keepalive
2024-10-25 13:13:00,762 DEBUG   HandlerThread:54224 [handler.py:handle_request():146] handle_request: keepalive
2024-10-25 13:13:04,571 ERROR   SenderThread:54224 [internal_api.py:execute():373] 409 response executing GraphQL.
2024-10-25 13:13:04,572 ERROR   SenderThread:54224 [internal_api.py:execute():374] {"errors":[{"message":"run 3liyyvb3 was previously created and deleted; try a new run name","path":["upsertBucket"]}],"data":{"upsertBucket":null}}
2024-10-25 13:13:04,747 INFO    WriterThread:54224 [datastore.py:close():296] close: C:\Users\bais_\source\repos\Progetto\NLP-customer-classification\wandb\run-20241025_131013-3liyyvb3\run-3liyyvb3.wandb
2024-10-25 13:13:04,808 INFO    HandlerThread:54224 [handler.py:finish():869] shutting down handler
2024-10-25 13:13:04,883 ERROR   StreamThr :54224 [internal.py:wandb_internal():174] Thread SenderThread:
Traceback (most recent call last):
  File "C:\Users\bais_\anaconda3\Lib\site-packages\wandb\apis\normalize.py", line 41, in wrapper
    return func(*args, **kwargs)
           ^^^^^^^^^^^^^^^^^^^^^
  File "C:\Users\bais_\anaconda3\Lib\site-packages\wandb\sdk\internal\internal_api.py", line 2216, in upsert_run
    response = self.gql(
               ^^^^^^^^^
  File "C:\Users\bais_\anaconda3\Lib\site-packages\wandb\sdk\internal\internal_api.py", line 341, in gql
    ret = self._retry_gql(
          ^^^^^^^^^^^^^^^^
  File "C:\Users\bais_\anaconda3\Lib\site-packages\wandb\sdk\lib\retry.py", line 131, in __call__
    result = self._call_fn(*args, **kwargs)
             ^^^^^^^^^^^^^^^^^^^^^^^^^^^^^^
  File "C:\Users\bais_\anaconda3\Lib\site-packages\wandb\sdk\internal\internal_api.py", line 369, in execute
    return self.client.execute(*args, **kwargs)  # type: ignore
           ^^^^^^^^^^^^^^^^^^^^^^^^^^^^^^^^^^^^
  File "C:\Users\bais_\anaconda3\Lib\site-packages\wandb\vendor\gql-0.2.0\wandb_gql\client.py", line 52, in execute
    result = self._get_result(document, *args, **kwargs)
             ^^^^^^^^^^^^^^^^^^^^^^^^^^^^^^^^^^^^^^^^^^^
  File "C:\Users\bais_\anaconda3\Lib\site-packages\wandb\vendor\gql-0.2.0\wandb_gql\client.py", line 60, in _get_result
    return self.transport.execute(document, *args, **kwargs)
           ^^^^^^^^^^^^^^^^^^^^^^^^^^^^^^^^^^^^^^^^^^^^^^^^^
  File "C:\Users\bais_\anaconda3\Lib\site-packages\wandb\sdk\lib\gql_request.py", line 59, in execute
    request.raise_for_status()
  File "C:\Users\bais_\anaconda3\Lib\site-packages\requests\models.py", line 1021, in raise_for_status
    raise HTTPError(http_error_msg, response=self)
requests.exceptions.HTTPError: 409 Client Error: Conflict for url: https://api.wandb.ai/graphql

During handling of the above exception, another exception occurred:

Traceback (most recent call last):
  File "C:\Users\bais_\anaconda3\Lib\site-packages\wandb\sdk\internal\internal_util.py", line 49, in run
    self._run()
  File "C:\Users\bais_\anaconda3\Lib\site-packages\wandb\sdk\internal\internal_util.py", line 100, in _run
    self._process(record)
  File "C:\Users\bais_\anaconda3\Lib\site-packages\wandb\sdk\internal\internal.py", line 328, in _process
    self._sm.send(record)
  File "C:\Users\bais_\anaconda3\Lib\site-packages\wandb\sdk\internal\sender.py", line 385, in send
    send_handler(record)
  File "C:\Users\bais_\anaconda3\Lib\site-packages\wandb\sdk\internal\sender.py", line 407, in send_request
    send_handler(record)
  File "C:\Users\bais_\anaconda3\Lib\site-packages\wandb\sdk\internal\sender.py", line 635, in send_request_defer
    self.debounce(final=True)
  File "C:\Users\bais_\anaconda3\Lib\site-packages\wandb\sdk\internal\sender.py", line 536, in debounce
    self._maybe_update_config(always=final)
  File "C:\Users\bais_\anaconda3\Lib\site-packages\wandb\sdk\internal\sender.py", line 513, in _maybe_update_config
    self._debounce_config()
  File "C:\Users\bais_\anaconda3\Lib\site-packages\wandb\sdk\internal\sender.py", line 542, in _debounce_config
    self._api.upsert_run(
  File "C:\Users\bais_\anaconda3\Lib\site-packages\wandb\apis\normalize.py", line 51, in wrapper
    raise CommError(message, error)
wandb.errors.CommError: run 3liyyvb3 was previously created and deleted; try a new run name (Error 409: Conflict)
